<?xml version="1.0" encoding="UTF-8"?>
<testsuite name="app_tests.AppTest-20240306215602" tests="7" file="app_tests.py" time="0.136" timestamp="2024-03-06T21:56:04" failures="3" errors="0" skipped="0">
	<testcase classname="app_tests.AppTest" name="test_about" time="0.049" timestamp="2024-03-06T21:56:04"/>
	<testcase classname="app_tests.AppTest" name="test_get_group" time="0.003" timestamp="2024-03-06T21:56:04"/>
	<testcase classname="app_tests.AppTest" name="test_home" time="0.009" timestamp="2024-03-06T21:56:04"/>
	<testcase classname="app_tests.AppTest" name="test_view_group1" time="0.010" timestamp="2024-03-06T21:56:04"/>
	<testcase classname="app_tests.AppTest" name="test_create_group" time="0.036" timestamp="2024-03-06T21:56:04">
		<failure type="AssertionError" message=""><![CDATA[Traceback (most recent call last):
  File "C:\Program Files\WindowsApps\PythonSoftwareFoundation.Python.3.12_3.12.752.0_x64__qbz5n2kfra8p0\Lib\unittest\case.py", line 58, in testPartExecutor
    yield
  File "C:\Program Files\WindowsApps\PythonSoftwareFoundation.Python.3.12_3.12.752.0_x64__qbz5n2kfra8p0\Lib\unittest\case.py", line 634, in run
    self._callTestMethod(testMethod)
    ^^^^^^^^^^^^^^^^^
  File "C:\Program Files\WindowsApps\PythonSoftwareFoundation.Python.3.12_3.12.752.0_x64__qbz5n2kfra8p0\Lib\unittest\case.py", line 589, in _callTestMethod
    if method() is not None:
    ^^^^^^^^^^^^^^^^^
  File "c:\tmp\a1\groups\src\unittest\python\app_tests.py", line 40, in test_create_group
    assert 'Create a New Group' in response.get_data(as_text=True)
    ^^^^^^^^^^^^^^^^^
AssertionError
]]></failure>
	</testcase>
	<testcase classname="app_tests.AppTest" name="test_delete_group3" time="0.019" timestamp="2024-03-06T21:56:04">
		<failure type="AssertionError" message=""><![CDATA[Traceback (most recent call last):
  File "C:\Program Files\WindowsApps\PythonSoftwareFoundation.Python.3.12_3.12.752.0_x64__qbz5n2kfra8p0\Lib\unittest\case.py", line 58, in testPartExecutor
    yield
  File "C:\Program Files\WindowsApps\PythonSoftwareFoundation.Python.3.12_3.12.752.0_x64__qbz5n2kfra8p0\Lib\unittest\case.py", line 634, in run
    self._callTestMethod(testMethod)
    ^^^^^^^^^^^^^^^^^
  File "C:\Program Files\WindowsApps\PythonSoftwareFoundation.Python.3.12_3.12.752.0_x64__qbz5n2kfra8p0\Lib\unittest\case.py", line 589, in _callTestMethod
    if method() is not None:
    ^^^^^^^^^^^^^^^^^
  File "c:\tmp\a1\groups\src\unittest\python\app_tests.py", line 52, in test_delete_group3
    assert 'Welcome to DevOps Groups' in response.get_data(as_text=True)
    ^^^^^^^^^^^^^^^^^
AssertionError
]]></failure>
	</testcase>
	<testcase classname="app_tests.AppTest" name="test_edit_group3" time="0.011" timestamp="2024-03-06T21:56:04">
		<failure type="AssertionError" message=""><![CDATA[Traceback (most recent call last):
  File "C:\Program Files\WindowsApps\PythonSoftwareFoundation.Python.3.12_3.12.752.0_x64__qbz5n2kfra8p0\Lib\unittest\case.py", line 58, in testPartExecutor
    yield
  File "C:\Program Files\WindowsApps\PythonSoftwareFoundation.Python.3.12_3.12.752.0_x64__qbz5n2kfra8p0\Lib\unittest\case.py", line 634, in run
    self._callTestMethod(testMethod)
    ^^^^^^^^^^^^^^^^^
  File "C:\Program Files\WindowsApps\PythonSoftwareFoundation.Python.3.12_3.12.752.0_x64__qbz5n2kfra8p0\Lib\unittest\case.py", line 589, in _callTestMethod
    if method() is not None:
    ^^^^^^^^^^^^^^^^^
  File "c:\tmp\a1\groups\src\unittest\python\app_tests.py", line 47, in test_edit_group3
    assert 'Edit "Group 1"' in response.get_data(as_text=True)
    ^^^^^^^^^^^^^^^^^
AssertionError
]]></failure>
	</testcase>
</testsuite>
